package gdtest;

public class Q20 {
	
	public static void main(String[] args) {
		/*
			문제   예외 처리에 대한 설명중 잘못 된 것은 무엇입니까?
			
			1번보기   try 구문은 예외가 발생 할 것 같은 구문을 지정 한다.   
			2번보기   catch 구문은 예외 발생시 처리할 내용의 구문이 들어간다.   
			3번보기   finally 는 예외 발생 여부에 상관없이 수행될 내용의 구문이 들어간다.   
			4번보기   main 메서드에서도 throws 로 예외를 전가하면 처음 예외가 발생 되었던 메서드로 다시 전가 된다.
		
		
			함수/메서드 호출 구조 -> 스택 구조 (LIFO)
			main() -> a() -> b() -> c() -> d() 
			
			d에서 예외 발생
			1) try
			2) throws 예외 던지기
		*/
	}
}
